<mujoco model="x3">
  <compiler angle="radian" meshdir="./meshes/"/>
  <statistic meansize="0.177939" extent="1.9618" center="0.0465088 1.93584e-06 -0.21519"/>
  <default>
    <joint damping="0.1" armature="0.01" frictionloss="0.1"/>
  </default>
  <asset>
    <texture type="skybox" builtin="gradient" width="128" height="128" rgb1="0.4 0.6 0.8" rgb2="0 0 0"/>
    <texture name="plane" type="2d" builtin="checker" rgb1="0.2 0.2 0.2" rgb2="0.3 0.3 0.3" width="512"
              height="512"/>
    <material name="plane" reflectance="0.0" texture="plane" texrepeat="1 1" texuniform="true"/>
    <mesh name="pelvis" file="pelvis.STL"/>
    <mesh name="left_hip_pitch_link" file="left_hip_pitch_link.STL"/>
    <mesh name="left_hip_roll_link" file="left_hip_roll_link.STL"/>
    <mesh name="left_hip_yaw_link" file="left_hip_yaw_link.STL"/>
    <mesh name="left_knee_link" file="left_knee_link.STL"/>
    <mesh name="left_ankle_pitch_link" file="left_ankle_pitch_link.STL"/>
    <mesh name="left_ankle_roll_link" file="left_ankle_roll_link.STL"/>
    <mesh name="right_hip_pitch_link" file="right_hip_pitch_link.STL"/>
    <mesh name="right_hip_roll_link" file="right_hip_roll_link.STL"/>
    <mesh name="right_hip_yaw_link" file="right_hip_yaw_link.STL"/>
    <mesh name="right_knee_link" file="right_knee_link.STL"/>
    <mesh name="right_ankle_pitch_link" file="right_ankle_pitch_link.STL"/>
    <mesh name="right_ankle_roll_link" file="right_ankle_roll_link.STL"/>
    <mesh name="waist_roll_link" file="waist_roll_link.STL"/>
    <mesh name="torso_link" file="torso_link.STL"/>
    <mesh name="left_shoulder_pitch_link" file="left_shoulder_pitch_link.STL"/>
    <mesh name="left_shoulder_roll_link" file="left_shoulder_roll_link.STL"/>
    <mesh name="left_shoulder_yaw_link" file="left_shoulder_yaw_link.STL"/>
    <mesh name="left_elbow_link" file="left_elbow_link.STL"/>
    <mesh name="left_wrist_roll_link" file="left_wrist_roll_link.STL"/>
    <mesh name="left_wrist_pitch_link" file="left_wrist_pitch_link.STL"/>
    <mesh name="left_wrist_yaw_link" file="left_wrist_yaw_link.STL"/>
    <mesh name="right_shoulder_pitch_link" file="right_shoulder_pitch_link.STL"/>
    <mesh name="right_shoulder_roll_link" file="right_shoulder_roll_link.STL"/>
    <mesh name="right_shoulder_yaw_link" file="right_shoulder_yaw_link.STL"/>
    <mesh name="right_elbow_link" file="right_elbow_link.STL"/>
    <mesh name="right_wrist_roll_link" file="right_wrist_roll_link.STL"/>
    <mesh name="right_wrist_pitch_link" file="right_wrist_pitch_link.STL"/>
    <mesh name="right_wrist_yaw_link" file="right_wrist_yaw_link.STL"/>
  </asset>

  <worldbody>
    <geom name="floor" pos="0.001 0 0" size="100 10 .125" type="plane" material="plane" condim="3"
          conaffinity="15" friction="0.6 0.6 0.001"/>
    <light mode="trackcom" pos="0 0 5" dir="0 0 -1"/>
    <body name="pelvis" pos="0 0 0.893">
      <inertial pos="0 0 0.115776" quat="0.706889 2.91347e-06 -1.28611e-05 0.707324" mass="3.65" diaginertia="0.0190501 0.0184655 0.0127755"/>
      <joint name="floating_base_joint" type="free" limited="false" actuatorfrclimited="false"/>
      <geom type="mesh" contype="0" conaffinity="0" group="1" density="0" rgba="1 1 1 1" mesh="pelvis"/>
      <geom type="mesh" rgba="1 1 1 1" mesh="pelvis"/>
      <body name="left_hip_pitch_link" pos="0 0.056998 0.044">
        <inertial pos="-7.014e-05 0.0416974 -0.0205686" quat="0.707107 0 0 0.707107" mass="2.167" diaginertia="0.00797221 0.00622358 0.00524355"/>
        <joint name="left_hip_pitch_joint" pos="0 0 0" axis="0 1 0" range="-2.3562 2.3562" actuatorfrcrange="-75 75"/>
        <geom type="mesh" contype="0" conaffinity="0" group="1" density="0" rgba="1 1 1 1" mesh="left_hip_pitch_link"/>
        <geom type="mesh" rgba="1 1 1 1" mesh="left_hip_pitch_link"/>
        <body name="left_hip_roll_link" pos="0 0.040491 -0.044">
          <inertial pos="0 0 -0.0331391" quat="0.5 0.5 -0.5 0.5" mass="0.05" diaginertia="5.63e-06 4.48e-06 4.48e-06"/>
          <joint name="left_hip_roll_joint" pos="0 0 0" axis="1 0 0" range="-0.5236 1.6581" actuatorfrcrange="-140.2 140.2"/>
          <geom type="mesh" contype="0" conaffinity="0" group="1" density="0" rgba="1 1 1 1" mesh="left_hip_roll_link"/>
          <geom type="mesh" rgba="1 1 1 1" mesh="left_hip_roll_link"/>
          <body name="left_hip_yaw_link">
            <inertial pos="0.00240937 0 -0.17118" quat="0.713733 0.0149082 0.0152113 0.700094" mass="2.4" diaginertia="0.0159371 0.015934 0.00374552"/>
            <joint name="left_hip_yaw_joint" pos="0 0 0" axis="0 0 1" range="-1.9199 3.1416" actuatorfrcrange="-88.2 88.2"/>
            <geom type="mesh" contype="0" conaffinity="0" group="1" density="0" rgba="1 1 1 1" mesh="left_hip_yaw_link"/>
            <body name="left_knee_link" pos="0 0 -0.339">
              <inertial pos="0.00029886 0 -0.210705" quat="0.707071 -0.00708323 -0.00708323 0.707071" mass="1.5" diaginertia="0.0162746 0.0159095 0.00146519"/>
              <joint name="left_knee_joint" pos="0 0 0" axis="0 1 0" range="0 2.3562" actuatorfrcrange="-140.2 140.2"/>
              <geom type="mesh" contype="0" conaffinity="0" group="1" density="0" rgba="1 1 1 1" mesh="left_knee_link"/>
              <geom type="mesh" rgba="1 1 1 1" mesh="left_knee_link"/>
              <body name="left_ankle_pitch_link" pos="0 0 -0.45">
                <inertial pos="0.00046495 0 -0.0356267" quat="0.707107 0 0 0.707107" mass="0.5" diaginertia="0.00048777 0.00043979 0.00019678"/>
                <joint name="left_ankle_pitch_joint" pos="0 0 0" axis="0 1 0" range="-1.0472 1.0472" actuatorfrcrange="-50.6 50.6"/>
                <geom type="mesh" contype="0" conaffinity="0" group="1" density="0" rgba="1 1 1 1" mesh="left_ankle_pitch_link"/>
                <geom type="mesh" rgba="1 1 1 1" mesh="left_ankle_pitch_link"/>
                <body name="left_ankle_roll_link" pos="0 0 -0.058">
                  <inertial pos="0.0527895 -8e-06 -0.0124553" quat="0.000151237 0.694503 0.000124693 0.719489" mass="1" diaginertia="0.00650771 0.00629204 0.000969317"/>
                  <joint name="left_ankle_roll_joint" pos="0 0 0" axis="1 0 0" range="-0.5236 0.5236" actuatorfrcrange="-50 50"/>
                  <geom type="mesh" contype="0" conaffinity="0" group="1" density="0" rgba="1 1 1 1" mesh="left_ankle_roll_link"/>
                  <geom size="0.005" pos="-0.085 0 -0.036" rgba="1 1 1 1"/>
                  <geom size="0.005" pos="-0.035 0.034 -0.036" rgba="1 1 1 1"/>
                  <geom size="0.005" pos="-0.035 -0.034 -0.036" rgba="1 1 1 1"/>
                  <geom size="0.005" pos="0.12 0.045 -0.036" rgba="1 1 1 1"/>
                  <geom size="0.005" pos="0.12 -0.045 -0.036" rgba="1 1 1 1"/>
                  <geom size="0.005" pos="0.18 0 -0.036" rgba="1 1 1 1"/>
                  <geom size="0.01 0.05" pos="0.08 -0.026 -0.024" quat="0.707105 0 0.707108 0" type="cylinder" rgba="1 1 1 1"/>
                  <geom size="0.01 0.1" pos="0.044 -0.018 -0.024" quat="0.707105 0 -0.707108 0" type="cylinder" rgba="1 1 1 1"/>
                  <geom size="0.01 0.12" pos="0.046 -0.01 -0.024" quat="0.707105 0 -0.707108 0" type="cylinder" rgba="1 1 1 1"/>
                  <geom size="0.01 0.125" pos="0.048 0 -0.024" quat="0.707105 0 -0.707108 0" type="cylinder" rgba="1 1 1 1"/>
                  <geom size="0.01 0.12" pos="0.046 0.01 -0.024" quat="0.707105 0 -0.707108 0" type="cylinder" rgba="1 1 1 1"/>
                  <geom size="0.01 0.1" pos="0.044 0.018 -0.024" quat="0.707105 0 -0.707108 0" type="cylinder" rgba="1 1 1 1"/>
                  <geom size="0.01 0.05" pos="0.08 0.026 -0.024" quat="0.707105 0 0.707108 0" type="cylinder" rgba="1 1 1 1"/>
                </body>
              </body>
            </body>
          </body>
        </body>
      </body>
      <body name="right_hip_pitch_link" pos="0 -0.056998 0.044">
        <inertial pos="-7.014e-05 -0.0416974 -0.0205686" quat="0.707107 0 0 0.707107" mass="2.167" diaginertia="0.00797221 0.00622358 0.00524355"/>
        <joint name="right_hip_pitch_joint" pos="0 0 0" axis="0 1 0" range="-2.3562 2.3562" actuatorfrcrange="-88 88"/>
        <geom type="mesh" contype="0" conaffinity="0" group="1" density="0" rgba="1 1 1 1" mesh="right_hip_pitch_link"/>
        <geom type="mesh" rgba="1 1 1 1" mesh="right_hip_pitch_link"/>
        <body name="right_hip_roll_link" pos="0 -0.040491 -0.044">
          <inertial pos="0 0 -0.0331391" quat="0.5 0.5 -0.5 0.5" mass="0.05" diaginertia="5.63e-06 4.48e-06 4.48e-06"/>
          <joint name="right_hip_roll_joint" pos="0 0 0" axis="1 0 0" range="-1.6581 0.5236" actuatorfrcrange="-140.2 140.2"/>
          <geom type="mesh" contype="0" conaffinity="0" group="1" density="0" rgba="1 1 1 1" mesh="right_hip_roll_link"/>
          <geom type="mesh" rgba="1 1 1 1" mesh="right_hip_roll_link"/>
          <body name="right_hip_yaw_link">
            <inertial pos="0.00240937 0 -0.17118" quat="0.713733 0.0149082 0.0152113 0.700094" mass="2.4" diaginertia="0.0159371 0.015934 0.00374552"/>
            <joint name="right_hip_yaw_joint" pos="0 0 0" axis="0 0 1" range="-3.1416 1.9199" actuatorfrcrange="-88.2 88.2"/>
            <geom type="mesh" contype="0" conaffinity="0" group="1" density="0" rgba="1 1 1 1" mesh="right_hip_yaw_link"/>
            <body name="right_knee_link" pos="0 0 -0.339">
              <inertial pos="0.00029886 0 -0.210705" quat="0.707071 -0.00708323 -0.00708323 0.707071" mass="1.5" diaginertia="0.0162746 0.0159095 0.00146519"/>
              <joint name="right_knee_joint" pos="0 0 0" axis="0 1 0" range="0 2.3562" actuatorfrcrange="-140.2 140.2"/>
              <geom type="mesh" contype="0" conaffinity="0" group="1" density="0" rgba="1 1 1 1" mesh="right_knee_link"/>
              <geom type="mesh" rgba="1 1 1 1" mesh="right_knee_link"/>
              <body name="right_ankle_pitch_link" pos="0 0 -0.45">
                <inertial pos="0.00046495 0 -0.0356267" quat="0.707107 0 0 0.707107" mass="0.5" diaginertia="0.00048777 0.00043979 0.00019678"/>
                <joint name="right_ankle_pitch_joint" pos="0 0 0" axis="0 1 0" range="-1.0472 1.0472" actuatorfrcrange="-50.6 50.6"/>
                <geom type="mesh" contype="0" conaffinity="0" group="1" density="0" rgba="1 1 1 1" mesh="right_ankle_pitch_link"/>
                <geom type="mesh" rgba="1 1 1 1" mesh="right_ankle_pitch_link"/>
                <body name="right_ankle_roll_link" pos="0 0 -0.058">
                  <inertial pos="0.0527895 -8e-06 -0.0124553" quat="0.000151237 0.694503 0.000124693 0.719489" mass="1" diaginertia="0.00650771 0.00629204 0.000969317"/>
                  <joint name="right_ankle_roll_joint" pos="0 0 0" axis="1 0 0" range="-0.5236 0.5236" actuatorfrcrange="-50 50"/>
                  <geom type="mesh" contype="0" conaffinity="0" group="1" density="0" rgba="1 1 1 1" mesh="right_ankle_roll_link"/>
                  <geom size="0.005" pos="-0.085 0 -0.036" rgba="1 1 1 1"/>
                  <geom size="0.005" pos="-0.035 0.034 -0.036" rgba="1 1 1 1"/>
                  <geom size="0.005" pos="-0.035 -0.034 -0.036" rgba="1 1 1 1"/>
                  <geom size="0.005" pos="0.12 0.045 -0.036" rgba="1 1 1 1"/>
                  <geom size="0.005" pos="0.12 -0.045 -0.036" rgba="1 1 1 1"/>
                  <geom size="0.005" pos="0.18 0 -0.036" rgba="1 1 1 1"/>
                  <geom size="0.01 0.05" pos="0.08 -0.026 -0.024" quat="0.707105 0 0.707108 0" type="cylinder" rgba="1 1 1 1"/>
                  <geom size="0.01 0.1" pos="0.044 -0.018 -0.024" quat="0.707105 0 -0.707108 0" type="cylinder" rgba="1 1 1 1"/>
                  <geom size="0.01 0.12" pos="0.046 -0.01 -0.024" quat="0.707105 0 -0.707108 0" type="cylinder" rgba="1 1 1 1"/>
                  <geom size="0.01 0.125" pos="0.048 0 -0.024" quat="0.707105 0 -0.707108 0" type="cylinder" rgba="1 1 1 1"/>
                  <geom size="0.01 0.12" pos="0.046 0.01 -0.024" quat="0.707105 0 -0.707108 0" type="cylinder" rgba="1 1 1 1"/>
                  <geom size="0.01 0.1" pos="0.044 0.018 -0.024" quat="0.707105 0 -0.707108 0" type="cylinder" rgba="1 1 1 1"/>
                  <geom size="0.01 0.05" pos="0.08 0.026 -0.024" quat="0.707105 0 0.707108 0" type="cylinder" rgba="1 1 1 1"/>
                </body>
              </body>
            </body>
          </body>
        </body>
      </body>
      <body name="waist_roll_link" pos="0 0 0.1945">
        <inertial pos="0 0 0" mass="0.05" diaginertia="5.63e-06 4.48e-06 4.48e-06"/>
        <joint name="waist_roll_joint" pos="0 0 0" axis="1 0 0" range="-0.3491 0.3491" actuatorfrcrange="-60.2 60.2"/>
        <geom type="mesh" contype="0" conaffinity="0" group="1" density="0" rgba="1 1 1 1" mesh="waist_roll_link"/>
        <body name="torso_link">
          <inertial pos="-0.00239171 -3.74e-06 0.179632" quat="0.99958 -1.89996e-05 0.0289681 2.12082e-05" mass="3" diaginertia="0.027699 0.0252883 0.0167502"/>
          <joint name="waist_yaw_joint" pos="0 0 0" axis="0 0 1" range="-1.8326 1.8326" actuatorfrcrange="-60.2 60.2"/>
          <geom type="mesh" contype="0" conaffinity="0" group="1" density="0" rgba="1 1 1 1" mesh="torso_link"/>
          <body name="left_shoulder_pitch_link" pos="-0.012293 0.12327 0.2885">
            <inertial pos="1.04e-06 0.0255119 0" quat="3.0798e-05 0.707075 -3.25061e-05 0.707138" mass="1.22" diaginertia="0.00148131 0.00148057 0.00125717"/>
            <joint name="left_shoulder_pitch_joint" pos="0 0 0" axis="0 1 0" range="-3.1416 1.5708" actuatorfrcrange="-50 50"/>
            <geom type="mesh" contype="0" conaffinity="0" group="1" density="0" rgba="1 1 1 1" mesh="left_shoulder_pitch_link"/>
            <geom type="mesh" rgba="1 1 1 1" mesh="left_shoulder_pitch_link"/>
            <body name="left_shoulder_roll_link" pos="0 0.033483 0" quat="0.999048 0.0436192 0 0">
              <inertial pos="0 0 0" mass="0.05" diaginertia="5.63e-06 4.48e-06 4.48e-06"/>
              <joint name="left_shoulder_roll_joint" pos="0 0 0" axis="1 0 0" range="0 3.0543" actuatorfrcrange="-50.6 50.6"/>
              <geom type="mesh" contype="0" conaffinity="0" group="1" density="0" rgba="1 1 1 1" mesh="left_shoulder_roll_link"/>
              <geom type="mesh" rgba="1 1 1 1" mesh="left_shoulder_roll_link"/>
              <body name="left_shoulder_yaw_link">
                <inertial pos="-0.00272365 -1.49e-06 -0.13946" quat="0.706745 -0.0224177 -0.0224085 0.706758" mass="1.5" diaginertia="0.00652221 0.00631223 0.00168329"/>
                <joint name="left_shoulder_yaw_joint" pos="0 0 0" axis="0 0 1" range="-2.0071 2.0071" actuatorfrcrange="-50.6 50.6"/>
                <geom type="mesh" contype="0" conaffinity="0" group="1" density="0" rgba="1 1 1 1" mesh="left_shoulder_yaw_link"/>
                <body name="left_elbow_link" pos="0 0 -0.23">
                  <inertial pos="0.01482 -1.87e-06 0.00294173" quat="0.701788 -0.083142 -0.0834852 0.702575" mass="0.5" diaginertia="0.00029095 0.000274622 0.000267458"/>
                  <joint name="left_elbow_joint" pos="0 0 0" axis="0 1 0" range="-0.4363 1.5708" actuatorfrcrange="-50.8 50.8"/>
                  <geom type="mesh" contype="0" conaffinity="0" group="1" density="0" rgba="1 1 1 1" mesh="left_elbow_link"/>
                  <geom type="mesh" rgba="1 1 1 1" mesh="left_elbow_link"/>
                  <body name="left_wrist_roll_link">
                    <inertial pos="0.130726 0 -2.867e-05" quat="0 0.706882 0 0.707332" mass="0.85" diaginertia="0.0023166 0.00228248 0.000430139"/>
                    <joint name="left_wrist_roll_joint" pos="0 0 0" axis="1 0 0" range="-2.0071 2.0071" actuatorfrcrange="-20.8 20.8"/>
                    <geom type="mesh" contype="0" conaffinity="0" group="1" density="0" rgba="1 1 1 1" mesh="left_wrist_roll_link"/>
                    <geom type="mesh" rgba="1 1 1 1" mesh="left_wrist_roll_link"/>
                    <body name="left_wrist_pitch_link" pos="0.235 0 0">
                      <inertial pos="0.0125817 0 0" quat="0 0.707107 0 0.707107" mass="0.05" diaginertia="9.1e-06 7.46e-06 4.12e-06"/>
                      <joint name="left_wrist_pitch_joint" pos="0 0 0" axis="0 1 0" range="-0.6981 0.6981" actuatorfrcrange="-20.8 20.8"/>
                      <geom type="mesh" contype="0" conaffinity="0" group="1" density="0" rgba="1 1 1 1" mesh="left_wrist_pitch_link"/>
                      <geom type="mesh" rgba="1 1 1 1" mesh="left_wrist_pitch_link"/>
                      <body name="left_wrist_yaw_link" pos="0.0215 0 0">
                        <inertial pos="0.0503439 -0.00067096 0.00221444" quat="0.530369 0.443563 0.580768 0.429733" mass="0.055" diaginertia="0.000163965 0.000149826 2.98683e-05"/>
                        <joint name="left_wrist_yaw_joint" pos="0 0 0" axis="0 0 1" range="-0.8727 0.8727" actuatorfrcrange="-20.4 20.4"/>
                        <geom type="mesh" contype="0" conaffinity="0" group="1" density="0" rgba="1 1 1 1" mesh="left_wrist_yaw_link"/>
                      </body>
                    </body>
                  </body>
                </body>
              </body>
            </body>
          </body>
          <body name="right_shoulder_pitch_link" pos="-0.012293 -0.12327 0.2885">
            <inertial pos="1.04e-06 0.0255119 0" quat="3.0798e-05 0.707075 -3.25061e-05 0.707138" mass="1.22" diaginertia="0.00148131 0.00148057 0.00125717"/>
            <joint name="right_shoulder_pitch_joint" pos="0 0 0" axis="0 1 0" range="-3.1416 1.5708" actuatorfrcrange="-50 50"/>
            <geom type="mesh" contype="0" conaffinity="0" group="1" density="0" rgba="1 1 1 1" mesh="right_shoulder_pitch_link"/>
            <geom type="mesh" rgba="1 1 1 1" mesh="right_shoulder_pitch_link"/>
            <body name="right_shoulder_roll_link" pos="0 -0.033479 0" quat="0.999048 -0.0436192 0 0">
              <inertial pos="0 0 0" mass="0.05" diaginertia="5.63e-06 4.48e-06 4.48e-06"/>
              <joint name="right_shoulder_roll_joint" pos="0 0 0" axis="1 0 0" range="-3.0543 0" actuatorfrcrange="-22.6 22.6"/>
              <geom type="mesh" contype="0" conaffinity="0" group="1" density="0" rgba="1 1 1 1" mesh="right_shoulder_roll_link"/>
              <geom type="mesh" rgba="1 1 1 1" mesh="right_shoulder_roll_link"/>
              <body name="right_shoulder_yaw_link">
                <inertial pos="-0.00272365 -1.49e-06 -0.13946" quat="0.706745 -0.0224177 -0.0224085 0.706758" mass="1.5" diaginertia="0.00652221 0.00631223 0.00168329"/>
                <joint name="right_shoulder_yaw_joint" pos="0 0 0" axis="0 0 1" range="-2.0071 2.0071" actuatorfrcrange="-22.6 22.6"/>
                <geom type="mesh" contype="0" conaffinity="0" group="1" density="0" rgba="1 1 1 1" mesh="right_shoulder_yaw_link"/>
                <body name="right_elbow_link" pos="0 0 -0.23">
                  <inertial pos="0.01482 -1.87e-06 0.00294173" quat="0.701788 -0.083142 -0.0834852 0.702575" mass="0.5" diaginertia="0.00029095 0.000274622 0.000267458"/>
                  <joint name="right_elbow_joint" pos="0 0 0" axis="0 1 0" range="-0.4363 1.5708" actuatorfrcrange="-18.8 18.8"/>
                  <geom type="mesh" contype="0" conaffinity="0" group="1" density="0" rgba="1 1 1 1" mesh="right_elbow_link"/>
                  <geom type="mesh" rgba="1 1 1 1" mesh="right_elbow_link"/>
                  <body name="right_wrist_roll_link">
                    <inertial pos="0.130726 0 -2.867e-05" quat="0 0.706882 0 0.707332" mass="0.85" diaginertia="0.0023166 0.00228248 0.000430139"/>
                    <joint name="right_wrist_roll_joint" pos="0 0 0" axis="1 0 0" range="-2.0071 2.0071" actuatorfrcrange="-18.8 18.8"/>
                    <geom type="mesh" contype="0" conaffinity="0" group="1" density="0" rgba="1 1 1 1" mesh="right_wrist_roll_link"/>
                    <geom type="mesh" rgba="1 1 1 1" mesh="right_wrist_roll_link"/>
                    <body name="right_wrist_pitch_link" pos="0.235 0 0">
                      <inertial pos="0.0125817 0 0" quat="0 0.707107 0 0.707107" mass="0.05" diaginertia="9.1e-06 7.46e-06 4.12e-06"/>
                      <joint name="right_wrist_pitch_joint" pos="0 0 0" axis="0 1 0" range="-0.6981 0.6981" actuatorfrcrange="-20.8 20.8"/>
                      <geom type="mesh" contype="0" conaffinity="0" group="1" density="0" rgba="1 1 1 1" mesh="right_wrist_pitch_link"/>
                      <geom type="mesh" rgba="1 1 1 1" mesh="right_wrist_pitch_link"/>
                      <body name="right_wrist_yaw_link" pos="0.0215 0 0">
                        <inertial pos="0.0503439 -0.00067096 0.00221444" quat="0.530369 0.443563 0.580768 0.429733" mass="0.055" diaginertia="0.000163965 0.000149826 2.98683e-05"/>
                        <joint name="right_wrist_yaw_joint" pos="0 0 0" axis="0 0 1" range="-0.8727 0.8727" actuatorfrcrange="-20.4 20.4"/>
                        <geom type="mesh" contype="0" conaffinity="0" group="1" density="0" rgba="1 1 1 1" mesh="right_wrist_yaw_link"/>
                      </body>
                    </body>
                  </body>
                </body>
              </body>
            </body>
          </body>
        </body>
      </body>
    </body>
  </worldbody>


  <actuator>
    <motor name="left_hip_pitch_joint" joint="left_hip_pitch_joint"/>
    <motor name="left_hip_roll_joint" joint="left_hip_roll_joint"/>
    <motor name="left_hip_yaw_joint" joint="left_hip_yaw_joint"/>
    <motor name="left_knee_joint" joint="left_knee_joint"/>
    <motor name="left_ankle_pitch_joint" joint="left_ankle_pitch_joint"/>
    <motor name="left_ankle_roll_joint" joint="left_ankle_roll_joint"/>
    <motor name="right_hip_pitch_joint" joint="right_hip_pitch_joint"/>
    <motor name="right_hip_roll_joint" joint="right_hip_roll_joint"/>
    <motor name="right_hip_yaw_joint" joint="right_hip_yaw_joint"/>
    <motor name="right_knee_joint" joint="right_knee_joint"/>
    <motor name="right_ankle_pitch_joint" joint="right_ankle_pitch_joint"/>
    <motor name="right_ankle_roll_joint" joint="right_ankle_roll_joint"/>
    <motor name="waist_roll_joint" joint="waist_roll_joint"/>
    <motor name="waist_yaw_joint" joint="waist_yaw_joint"/>
    <motor name="left_shoulder_pitch_joint" joint="left_shoulder_pitch_joint"/>
    <motor name="left_shoulder_roll_joint" joint="left_shoulder_roll_joint"/>
    <motor name="left_shoulder_yaw_joint" joint="left_shoulder_yaw_joint"/>
    <motor name="left_elbow_joint" joint="left_elbow_joint"/>
    <motor name="left_wrist_roll_joint" joint="left_wrist_roll_joint"/>
    <motor name="left_wrist_pitch_joint" joint="left_wrist_pitch_joint"/>
    <motor name="left_wrist_yaw_joint" joint="left_wrist_yaw_joint"/>
    <motor name="right_shoulder_pitch_joint" joint="right_shoulder_pitch_joint"/>
    <motor name="right_shoulder_roll_joint" joint="right_shoulder_roll_joint"/>
    <motor name="right_shoulder_yaw_joint" joint="right_shoulder_yaw_joint"/>
    <motor name="right_elbow_joint" joint="right_elbow_joint"/>
    <motor name="right_wrist_roll_joint" joint="right_wrist_roll_joint"/>
    <motor name="right_wrist_pitch_joint" joint="right_wrist_pitch_joint"/>
    <motor name="right_wrist_yaw_joint" joint="right_wrist_yaw_joint"/>
  </actuator>

</mujoco>
